Workbook
Name ind: 'TRA calculation'!$AC$5:$AC$8
Name ind_pro: 'TRA calculation'!$AB$5:$AB$7
Name indpro: 'TRA calculation'!$AB$5:$AB$8
Name liquid: 'TRA calculation'!$Y$5:$Y$8
Name phys.state: 'TRA calculation'!$X$5:$X$6
Name pro: 'TRA calculation'!$AD$6:$AD$8
Name prof: 'TRA calculation'!$AD$5:$AD$8
Name solid: 'TRA calculation'!$Z$5:$Z$8

Sheet TRA calculation
A1: ECETOC TRA Worker version 3.2 (stand alone tool) | D1: DISCLAIMER: please note that the tool is provided for personal use only. It should not be copied or forwarded to third parties. The tool has been subjected to thorough testing. Despite this, ECETOC does not guarantee that the ECETOC TRA tool works error-free. ECETOC is making this tool available for users to aid them in the risk assessment of their materials. ECETOC offers no warranty either to the reliability of the tool and of the provided information or to the conclusions or assumptions made by any user on the basis of the use of this tool or the use of such information. All usage is at the discretion of the user and ECETOC is not liable for any consequences resulting from such use.
F4: Reference values (DNEL or OEL): | J4: How to select the correct fugacity band for liquids | P4: How to select the correct fugacity band for solids | X4: phys.state | Y4: liquid | Z4: solid | AB4: indpro | AC4: ind | AD4: prof
A5: Substance name: | P5: General description | R5: Relative dustiness potential | T5: TRA fugacity | U5: Typical materials | X5: liquid | Y5: very low | Z5: low | AB5: ind | AC5: no PPE | AD5: no PPE
F6: Long-term inhalation: | H6: (mg/m3) | J6: Vapour pressure at operating temperature (Pa): | P6: Not dusty | R6: 1 | T6: Low | U6: Plastic granules, pelleted fertilisers | X6: solid | Y6: low | Z6: medium | AB6: prof | AC6: PPE80% | AD6: PPE80%
A7: CAS no: | F7: Long-term dermal: | H7: (mg/kg/day) | P7: Slightly dusty | R7: 10 - 100 times dustier | T7: Low | U7: Dry garden peat, sugar, salt | Y7: medium | Z7: high | AC7: PPE90% | AD7: PPE90%
F8: Short-term inhalation: | H8: (mg/m3) | J8: Fugacity band at this vapour pressure: | N8: =IF(N6<0.01,"very low",IF(AND(N6>=0.01,N6<500),"low",IF(AND(N6>=500,N6<=10000),"medium","high"))) -> very low | P8: Dusty | R8: 100-1000 times dustier | T8: Medium | U8: Talc, graphite | Y8: high | AC8: PPE95%
A9: Molecular weight: | C9: (g/mol) | F9: Local dermal: | H9: (µg/cm2) | P9: Very/extremely dusty | R9: > 1000 times dustier | T9: High | U9: Cement dust, milled powders, plaster, flour, lyophilised powders
A11: Scenario name | B11: PROC | C11: Ind/Prof | D11: Physical state | E11: Fugacity | F11: Ventilation | G11: Duration | H11: Concentration | I11: LEV | J11: RPE mask | K11: PPE gloves | L11: LEV for dermal | M11: Predicted 8hr inhalatory exposure (mg/m3) | N11: Predicted 8hr dermal exposure (mg/kg/day) | O11: Predicted short-term inhalatory exposure (mg/m3) | P11: Predicted local dermal exposure (µg/cm2) | Q11: RCR (long-term inhalation) | R11: RCR (long-term dermal) | S11: RCR (short-term inhalation) | T11: RCR (local dermal) | U11: Remarks | W11: Fugacity | X11: Ventilation Reduction Factor | Y11: Duration Reduction Factor (inhalation) | Z11: Duration Reduction Factor (dermal) | AA11: Concentration Reduction Factor | AB11: RPE Reduction Factor | AC11: PPE Reduction Factor | AD11: Multiplier short-term | AE11: Look-up descriptor | AF11: Initial estimate inhalation | AG11: Initial estimate dermal | AH11: Initial estimate dermal | AJ11: Message TRA only estimates vapour phase exposure | AK11: Message no reduction for LEV for PROC1 | AL11: Message no reduction for duration on dermal estimate
M12: =IF(AF12="n/a","change input",IF(AND(F12="outdoors",I12="yes"),"change input",IF(AND(C12="prof",F12="indoors - enhanced ventilation",I12="yes"),"change input",AF12*X12*Y12*AA12*AB12*VLOOKUP(AE12,TRAlookup!$A$2:$H$729,5,FALSE)))) -> change input | N12: =IF(OR(AG12="n/a",M12="change input"),"n/a",IF(L12="yes",AG12*Z12*AA12*AC12*VLOOKUP(AE12,TRAlookup!$A$2:$H$729,6,FALSE),AG12*Z12*AA12*AC12)) -> #N/A | O12: =IF(OR(M12="n/a",M12="change input"),"n/a",M12*AD12/Y12) -> n/a | P12: =IF(OR(AG12="n/a",M12="change input"),"n/a",IF(L12="yes",AH12*Z12*AA12*AC12*VLOOKUP(AE12,TRAlookup!$A$2:$H$729,6,FALSE),AH12*Z12*AA12*AC12)) -> #N/A | Q12: =IF(OR(M12="n/a",M12="change input"),"n/a",M12/$G$6) -> n/a | R12: =IF(N12="n/a","n/a",N12/$G$7) -> #N/A | S12: =IF(O12="n/a","n/a",O12/$G$8) -> n/a | T12: =IF(P12="n/a","n/a",P12/$G$9) -> #N/A | U12: =IF(AND(D12="solid",E12="very low"),"Incorrect fugacity for solids.",IF(AF12="n/a",VLOOKUP(AE12,TRAlookup!$A$2:$H$729,8,FALSE),IF(AND(F12="outdoors",I12="yes"),"Combination 'outdoors' and 'LEV' not allowed. ",IF(AND(C12="prof",F12="indoors - enhanced ventilation",I12="yes"),"Combination 'indoors - enhanced ventilation' and 'LEV' not allowed for professional setting. ",CONCATENATE(AJ12,AK12,AL12))))) -> #N/A | W12: =E12 -> 0 | X12: =IF(F12="outdoors",0.7, IF(F12="indoors - good ventilation",0.7, IF(F12="indoors - enhanced ventilation",0.3,1))) -> 1 | Y12: =IF(G12="<15min",0.1, IF(G12="15min-1hr",0.2, IF(G12="1-4hr",0.6,1))) -> 1 | Z12: =IF(AND(D12="solid",OR(W12="medium",W12="high")),1,IF(AND(D12="liquid",OR(W12="very low",W12="low")),1,Y12)) -> 1 | AA12: =IF(H12="<1%",0.1, IF(H12="1-5%",0.2, IF(H12="5-25%",0.6,1))) -> 1 | AB12: =IF(J12="RPE90%",0.1, IF(J12="RPE95%",0.05,1)) -> 1 | AC12: =IF(K12="PPE80%",0.2, IF(K12="PPE90%",0.1, IF(AND(C12="prof",K12="PPE95%"),0.1, IF(K12="PPE95%",0.05,1)))) -> 1 | AD12: =IF(AND(AND(D12="liquid",W12="very low"),NOT(OR(B12="PROC7",B12="PROC11",B12="PROC17",B12="PROC18",AND(B12="PROC10",I12="no"),AND(B12="PROC19",I12="no")))),1,4) -> 4 | AE12: =CONCATENATE(B12,D12,I12,W12,C12) -> 0 | AF12: =IF(AND(D12="solid",E12="very low"),"n/a",IF(D12="solid",VLOOKUP(AE12,TRAlookup!$A$2:$H$729,2,FALSE),IFERROR(VLOOKUP(AE12,TRAlookup!$A$2:$H$729,2,FALSE)*$B$9/24,"n/a"))) -> n/a | AG12: =IF(AND(D12="solid",E12="very low"),"n/a",VLOOKUP(AE12,TRAlookup!$A$2:$H$729,3,FALSE)) -> #N/A | AH12: =IF(AND(D12="solid",E12="very low"),"n/a",VLOOKUP(AE12,TRAlookup!$A$2:$H$729,4,FALSE)) -> #N/A | AJ12: =IF(AND(D12="liquid",OR(AND(B12="PROC7",C12="ind"),AND(B12="PROC10",I12="no"),AND(B12="PROC11",C12="prof"),OR(B12="PROC17",B12="PROC18"),AND(B12="PROC19",I12="no"))),"Note that the TRA predicts vapour phase exposure; exposure by aerosols is not taken into account; if aerosol formation is relevant, refer to other information or models. ","") | AK12: =IF(AND(B12="PROC1",I12="yes"),"No reduction for LEV for PROC1. ","") | AL12: =IF(Z12>Y12,"No reduction for duration on dermal estimate. ","")
M13: =IF(AF13="n/a","change input",IF(AND(F13="outdoors",I13="yes"),"change input",IF(AND(C13="prof",F13="indoors - enhanced ventilation",I13="yes"),"change input",AF13*X13*Y13*AA13*AB13*VLOOKUP(AE13,TRAlookup!$A$2:$H$729,5,FALSE)))) -> change input | N13: =IF(OR(AG13="n/a",M13="change input"),"n/a",IF(L13="yes",AG13*Z13*AA13*AC13*VLOOKUP(AE13,TRAlookup!$A$2:$H$729,6,FALSE),AG13*Z13*AA13*AC13)) -> #N/A | O13: =IF(OR(M13="n/a",M13="change input"),"n/a",M13*AD13/Y13) -> n/a | P13: =IF(OR(AG13="n/a",M13="change input"),"n/a",IF(L13="yes",AH13*Z13*AA13*AC13*VLOOKUP(AE13,TRAlookup!$A$2:$H$729,6,FALSE),AH13*Z13*AA13*AC13)) -> #N/A | Q13: =IF(OR(M13="n/a",M13="change input"),"n/a",M13/$G$6) -> n/a | R13: =IF(N13="n/a","n/a",N13/$G$7) -> #N/A | S13: =IF(O13="n/a","n/a",O13/$G$8) -> n/a | T13: =IF(P13="n/a","n/a",P13/$G$9) -> #N/A | U13: =IF(AND(D13="solid",E13="very low"),"Incorrect fugacity for solids.",IF(AF13="n/a",VLOOKUP(AE13,TRAlookup!$A$2:$H$729,8,FALSE),IF(AND(F13="outdoors",I13="yes"),"Combination 'outdoors' and 'LEV' not allowed. ",IF(AND(C13="prof",F13="indoors - enhanced ventilation",I13="yes"),"Combination 'indoors - enhanced ventilation' and 'LEV' not allowed for professional setting. ",CONCATENATE(AJ13,AK13,AL13))))) -> #N/A | W13: =E13 -> 0 | X13: =IF(F13="outdoors",0.7, IF(F13="indoors - good ventilation",0.7, IF(F13="indoors - enhanced ventilation",0.3,1))) -> 1 | Y13: =IF(G13="<15min",0.1, IF(G13="15min-1hr",0.2, IF(G13="1-4hr",0.6,1))) -> 1 | Z13: =IF(AND(D13="solid",OR(W13="medium",W13="high")),1,IF(AND(D13="liquid",OR(W13="very low",W13="low")),1,Y13)) -> 1 | AA13: =IF(H13="<1%",0.1, IF(H13="1-5%",0.2, IF(H13="5-25%",0.6,1))) -> 1 | AB13: =IF(J13="RPE90%",0.1, IF(J13="RPE95%",0.05,1)) -> 1 | AC13: =IF(K13="PPE80%",0.2, IF(K13="PPE90%",0.1, IF(AND(C13="prof",K13="PPE95%"),0.1, IF(K13="PPE95%",0.05,1)))) -> 1 | AD13: =IF(AND(AND(D13="liquid",W13="very low"),NOT(OR(B13="PROC7",B13="PROC11",B13="PROC17",B13="PROC18",AND(B13="PROC10",I13="no"),AND(B13="PROC19",I13="no")))),1,4) -> 4 | AE13: =CONCATENATE(B13,D13,I13,W13,C13) -> 0 | AF13: =IF(AND(D13="solid",E13="very low"),"n/a",IF(D13="solid",VLOOKUP(AE13,TRAlookup!$A$2:$H$729,2,FALSE),IFERROR(VLOOKUP(AE13,TRAlookup!$A$2:$H$729,2,FALSE)*$B$9/24,"n/a"))) -> n/a | AG13: =IF(AND(D13="solid",E13="very low"),"n/a",VLOOKUP(AE13,TRAlookup!$A$2:$H$729,3,FALSE)) -> #N/A | AH13: =IF(AND(D13="solid",E13="very low"),"n/a",VLOOKUP(AE13,TRAlookup!$A$2:$H$729,4,FALSE)) -> #N/A | AJ13: =IF(AND(D13="liquid",OR(AND(B13="PROC7",C13="ind"),AND(B13="PROC10",I13="no"),AND(B13="PROC11",C13="prof"),OR(B13="PROC17",B13="PROC18"),AND(B13="PROC19",I13="no"))),"Note that the TRA predicts vapour phase exposure; exposure by aerosols is not taken into account; if aerosol formation is relevant, refer to other information or models. ","") | AK13: =IF(AND(B13="PROC1",I13="yes"),"No reduction for LEV for PROC1. ","") | AL13: =IF(Z13>Y13,"No reduction for duration on dermal estimate. ","")
M14: =IF(AF14="n/a","change input",IF(AND(F14="outdoors",I14="yes"),"change input",IF(AND(C14="prof",F14="indoors - enhanced ventilation",I14="yes"),"change input",AF14*X14*Y14*AA14*AB14*VLOOKUP(AE14,TRAlookup!$A$2:$H$729,5,FALSE)))) -> change input | N14: =IF(OR(AG14="n/a",M14="change input"),"n/a",IF(L14="yes",AG14*Z14*AA14*AC14*VLOOKUP(AE14,TRAlookup!$A$2:$H$729,6,FALSE),AG14*Z14*AA14*AC14)) -> #N/A | O14: =IF(OR(M14="n/a",M14="change input"),"n/a",M14*AD14/Y14) -> n/a | P14: =IF(OR(AG14="n/a",M14="change input"),"n/a",IF(L14="yes",AH14*Z14*AA14*AC14*VLOOKUP(AE14,TRAlookup!$A$2:$H$729,6,FALSE),AH14*Z14*AA14*AC14)) -> #N/A | Q14: =IF(OR(M14="n/a",M14="change input"),"n/a",M14/$G$6) -> n/a | R14: =IF(N14="n/a","n/a",N14/$G$7) -> #N/A | S14: =IF(O14="n/a","n/a",O14/$G$8) -> n/a | T14: =IF(P14="n/a","n/a",P14/$G$9) -> #N/A | U14: =IF(AND(D14="solid",E14="very low"),"Incorrect fugacity for solids.",IF(AF14="n/a",VLOOKUP(AE14,TRAlookup!$A$2:$H$729,8,FALSE),IF(AND(F14="outdoors",I14="yes"),"Combination 'outdoors' and 'LEV' not allowed. ",IF(AND(C14="prof",F14="indoors - enhanced ventilation",I14="yes"),"Combination 'indoors - enhanced ventilation' and 'LEV' not allowed for professional setting. ",CONCATENATE(AJ14,AK14,AL14))))) -> #N/A | W14: =E14 -> 0 | X14: =IF(F14="outdoors",0.7, IF(F14="indoors - good ventilation",0.7, IF(F14="indoors - enhanced ventilation",0.3,1))) -> 1 | Y14: =IF(G14="<15min",0.1, IF(G14="15min-1hr",0.2, IF(G14="1-4hr",0.6,1))) -> 1 | Z14: =IF(AND(D14="solid",OR(W14="medium",W14="high")),1,IF(AND(D14="liquid",OR(W14="very low",W14="low")),1,Y14)) -> 1 | AA14: =IF(H14="<1%",0.1, IF(H14="1-5%",0.2, IF(H14="5-25%",0.6,1))) -> 1 | AB14: =IF(J14="RPE90%",0.1, IF(J14="RPE95%",0.05,1)) -> 1 | AC14: =IF(K14="PPE80%",0.2, IF(K14="PPE90%",0.1, IF(AND(C14="prof",K14="PPE95%"),0.1, IF(K14="PPE95%",0.05,1)))) -> 1 | AD14: =IF(AND(AND(D14="liquid",W14="very low"),NOT(OR(B14="PROC7",B14="PROC11",B14="PROC17",B14="PROC18",AND(B14="PROC10",I14="no"),AND(B14="PROC19",I14="no")))),1,4) -> 4 | AE14: =CONCATENATE(B14,D14,I14,W14,C14) -> 0 | AF14: =IF(AND(D14="solid",E14="very low"),"n/a",IF(D14="solid",VLOOKUP(AE14,TRAlookup!$A$2:$H$729,2,FALSE),IFERROR(VLOOKUP(AE14,TRAlookup!$A$2:$H$729,2,FALSE)*$B$9/24,"n/a"))) -> n/a | AG14: =IF(AND(D14="solid",E14="very low"),"n/a",VLOOKUP(AE14,TRAlookup!$A$2:$H$729,3,FALSE)) -> #N/A | AH14: =IF(AND(D14="solid",E14="very low"),"n/a",VLOOKUP(AE14,TRAlookup!$A$2:$H$729,4,FALSE)) -> #N/A | AJ14: =IF(AND(D14="liquid",OR(AND(B14="PROC7",C14="ind"),AND(B14="PROC10",I14="no"),AND(B14="PROC11",C14="prof"),OR(B14="PROC17",B14="PROC18"),AND(B14="PROC19",I14="no"))),"Note that the TRA predicts vapour phase exposure; exposure by aerosols is not taken into account; if aerosol formation is relevant, refer to other information or models. ","") | AK14: =IF(AND(B14="PROC1",I14="yes"),"No reduction for LEV for PROC1. ","") | AL14: =IF(Z14>Y14,"No reduction for duration on dermal estimate. ","")
M15: =IF(AF15="n/a","change input",IF(AND(F15="outdoors",I15="yes"),"change input",IF(AND(C15="prof",F15="indoors - enhanced ventilation",I15="yes"),"change input",AF15*X15*Y15*AA15*AB15*VLOOKUP(AE15,TRAlookup!$A$2:$H$729,5,FALSE)))) -> change input | N15: =IF(OR(AG15="n/a",M15="change input"),"n/a",IF(L15="yes",AG15*Z15*AA15*AC15*VLOOKUP(AE15,TRAlookup!$A$2:$H$729,6,FALSE),AG15*Z15*AA15*AC15)) -> #N/A | O15: =IF(OR(M15="n/a",M15="change input"),"n/a",M15*AD15/Y15) -> n/a | P15: =IF(OR(AG15="n/a",M15="change input"),"n/a",IF(L15="yes",AH15*Z15*AA15*AC15*VLOOKUP(AE15,TRAlookup!$A$2:$H$729,6,FALSE),AH15*Z15*AA15*AC15)) -> #N/A | Q15: =IF(OR(M15="n/a",M15="change input"),"n/a",M15/$G$6) -> n/a | R15: =IF(N15="n/a","n/a",N15/$G$7) -> #N/A | S15: =IF(O15="n/a","n/a",O15/$G$8) -> n/a | T15: =IF(P15="n/a","n/a",P15/$G$9) -> #N/A | U15: =IF(AND(D15="solid",E15="very low"),"Incorrect fugacity for solids.",IF(AF15="n/a",VLOOKUP(AE15,TRAlookup!$A$2:$H$729,8,FALSE),IF(AND(F15="outdoors",I15="yes"),"Combination 'outdoors' and 'LEV' not allowed. ",IF(AND(C15="prof",F15="indoors - enhanced ventilation",I15="yes"),"Combination 'indoors - enhanced ventilation' and 'LEV' not allowed for professional setting. ",CONCATENATE(AJ15,AK15,AL15))))) -> #N/A | W15: =E15 -> 0 | X15: =IF(F15="outdoors",0.7, IF(F15="indoors - good ventilation",0.7, IF(F15="indoors - enhanced ventilation",0.3,1))) -> 1 | Y15: =IF(G15="<15min",0.1, IF(G15="15min-1hr",0.2, IF(G15="1-4hr",0.6,1))) -> 1 | Z15: =IF(AND(D15="solid",OR(W15="medium",W15="high")),1,IF(AND(D15="liquid",OR(W15="very low",W15="low")),1,Y15)) -> 1 | AA15: =IF(H15="<1%",0.1, IF(H15="1-5%",0.2, IF(H15="5-25%",0.6,1))) -> 1 | AB15: =IF(J15="RPE90%",0.1, IF(J15="RPE95%",0.05,1)) -> 1 | AC15: =IF(K15="PPE80%",0.2, IF(K15="PPE90%",0.1, IF(AND(C15="prof",K15="PPE95%"),0.1, IF(K15="PPE95%",0.05,1)))) -> 1 | AD15: =IF(AND(AND(D15="liquid",W15="very low"),NOT(OR(B15="PROC7",B15="PROC11",B15="PROC17",B15="PROC18",AND(B15="PROC10",I15="no"),AND(B15="PROC19",I15="no")))),1,4) -> 4 | AE15: =CONCATENATE(B15,D15,I15,W15,C15) -> 0 | AF15: =IF(AND(D15="solid",E15="very low"),"n/a",IF(D15="solid",VLOOKUP(AE15,TRAlookup!$A$2:$H$729,2,FALSE),IFERROR(VLOOKUP(AE15,TRAlookup!$A$2:$H$729,2,FALSE)*$B$9/24,"n/a"))) -> n/a | AG15: =IF(AND(D15="solid",E15="very low"),"n/a",VLOOKUP(AE15,TRAlookup!$A$2:$H$729,3,FALSE)) -> #N/A | AH15: =IF(AND(D15="solid",E15="very low"),"n/a",VLOOKUP(AE15,TRAlookup!$A$2:$H$729,4,FALSE)) -> #N/A | AJ15: =IF(AND(D15="liquid",OR(AND(B15="PROC7",C15="ind"),AND(B15="PROC10",I15="no"),AND(B15="PROC11",C15="prof"),OR(B15="PROC17",B15="PROC18"),AND(B15="PROC19",I15="no"))),"Note that the TRA predicts vapour phase exposure; exposure by aerosols is not taken into account; if aerosol formation is relevant, refer to other information or models. ","") | AK15: =IF(AND(B15="PROC1",I15="yes"),"No reduction for LEV for PROC1. ","") | AL15: =IF(Z15>Y15,"No reduction for duration on dermal estimate. ","")
M16: =IF(AF16="n/a","change input",IF(AND(F16="outdoors",I16="yes"),"change input",IF(AND(C16="prof",F16="indoors - enhanced ventilation",I16="yes"),"change input",AF16*X16*Y16*AA16*AB16*VLOOKUP(AE16,TRAlookup!$A$2:$H$729,5,FALSE)))) -> change input | N16: =IF(OR(AG16="n/a",M16="change input"),"n/a",IF(L16="yes",AG16*Z16*AA16*AC16*VLOOKUP(AE16,TRAlookup!$A$2:$H$729,6,FALSE),AG16*Z16*AA16*AC16)) -> #N/A | O16: =IF(OR(M16="n/a",M16="change input"),"n/a",M16*AD16/Y16) -> n/a | P16: =IF(OR(AG16="n/a",M16="change input"),"n/a",IF(L16="yes",AH16*Z16*AA16*AC16*VLOOKUP(AE16,TRAlookup!$A$2:$H$729,6,FALSE),AH16*Z16*AA16*AC16)) -> #N/A | Q16: =IF(OR(M16="n/a",M16="change input"),"n/a",M16/$G$6) -> n/a | R16: =IF(N16="n/a","n/a",N16/$G$7) -> #N/A | S16: =IF(O16="n/a","n/a",O16/$G$8) -> n/a | T16: =IF(P16="n/a","n/a",P16/$G$9) -> #N/A | U16: =IF(AND(D16="solid",E16="very low"),"Incorrect fugacity for solids.",IF(AF16="n/a",VLOOKUP(AE16,TRAlookup!$A$2:$H$729,8,FALSE),IF(AND(F16="outdoors",I16="yes"),"Combination 'outdoors' and 'LEV' not allowed. ",IF(AND(C16="prof",F16="indoors - enhanced ventilation",I16="yes"),"Combination 'indoors - enhanced ventilation' and 'LEV' not allowed for professional setting. ",CONCATENATE(AJ16,AK16,AL16))))) -> #N/A | W16: =E16 -> 0 | X16: =IF(F16="outdoors",0.7, IF(F16="indoors - good ventilation",0.7, IF(F16="indoors - enhanced ventilation",0.3,1))) -> 1 | Y16: =IF(G16="<15min",0.1, IF(G16="15min-1hr",0.2, IF(G16="1-4hr",0.6,1))) -> 1 | Z16: =IF(AND(D16="solid",OR(W16="medium",W16="high")),1,IF(AND(D16="liquid",OR(W16="very low",W16="low")),1,Y16)) -> 1 | AA16: =IF(H16="<1%",0.1, IF(H16="1-5%",0.2, IF(H16="5-25%",0.6,1))) -> 1 | AB16: =IF(J16="RPE90%",0.1, IF(J16="RPE95%",0.05,1)) -> 1 | AC16: =IF(K16="PPE80%",0.2, IF(K16="PPE90%",0.1, IF(AND(C16="prof",K16="PPE95%"),0.1, IF(K16="PPE95%",0.05,1)))) -> 1 | AD16: =IF(AND(AND(D16="liquid",W16="very low"),NOT(OR(B16="PROC7",B16="PROC11",B16="PROC17",B16="PROC18",AND(B16="PROC10",I16="no"),AND(B16="PROC19",I16="no")))),1,4) -> 4 | AE16: =CONCATENATE(B16,D16,I16,W16,C16) -> 0 | AF16: =IF(AND(D16="solid",E16="very low"),"n/a",IF(D16="solid",VLOOKUP(AE16,TRAlookup!$A$2:$H$729,2,FALSE),IFERROR(VLOOKUP(AE16,TRAlookup!$A$2:$H$729,2,FALSE)*$B$9/24,"n/a"))) -> n/a | AG16: =IF(AND(D16="solid",E16="very low"),"n/a",VLOOKUP(AE16,TRAlookup!$A$2:$H$729,3,FALSE)) -> #N/A | AH16: =IF(AND(D16="solid",E16="very low"),"n/a",VLOOKUP(AE16,TRAlookup!$A$2:$H$729,4,FALSE)) -> #N/A | AJ16: =IF(AND(D16="liquid",OR(AND(B16="PROC7",C16="ind"),AND(B16="PROC10",I16="no"),AND(B16="PROC11",C16="prof"),OR(B16="PROC17",B16="PROC18"),AND(B16="PROC19",I16="no"))),"Note that the TRA predicts vapour phase exposure; exposure by aerosols is not taken into account; if aerosol formation is relevant, refer to other information or models. ","") | AK16: =IF(AND(B16="PROC1",I16="yes"),"No reduction for LEV for PROC1. ","") | AL16: =IF(Z16>Y16,"No reduction for duration on dermal estimate. ","")
M17: =IF(AF17="n/a","change input",IF(AND(F17="outdoors",I17="yes"),"change input",IF(AND(C17="prof",F17="indoors - enhanced ventilation",I17="yes"),"change input",AF17*X17*Y17*AA17*AB17*VLOOKUP(AE17,TRAlookup!$A$2:$H$729,5,FALSE)))) -> change input | N17: =IF(OR(AG17="n/a",M17="change input"),"n/a",IF(L17="yes",AG17*Z17*AA17*AC17*VLOOKUP(AE17,TRAlookup!$A$2:$H$729,6,FALSE),AG17*Z17*AA17*AC17)) -> #N/A | O17: =IF(OR(M17="n/a",M17="change input"),"n/a",M17*AD17/Y17) -> n/a | P17: =IF(OR(AG17="n/a",M17="change input"),"n/a",IF(L17="yes",AH17*Z17*AA17*AC17*VLOOKUP(AE17,TRAlookup!$A$2:$H$729,6,FALSE),AH17*Z17*AA17*AC17)) -> #N/A | Q17: =IF(OR(M17="n/a",M17="change input"),"n/a",M17/$G$6) -> n/a | R17: =IF(N17="n/a","n/a",N17/$G$7) -> #N/A | S17: =IF(O17="n/a","n/a",O17/$G$8) -> n/a | T17: =IF(P17="n/a","n/a",P17/$G$9) -> #N/A | U17: =IF(AND(D17="solid",E17="very low"),"Incorrect fugacity for solids.",IF(AF17="n/a",VLOOKUP(AE17,TRAlookup!$A$2:$H$729,8,FALSE),IF(AND(F17="outdoors",I17="yes"),"Combination 'outdoors' and 'LEV' not allowed. ",IF(AND(C17="prof",F17="indoors - enhanced ventilation",I17="yes"),"Combination 'indoors - enhanced ventilation' and 'LEV' not allowed for professional setting. ",CONCATENATE(AJ17,AK17,AL17))))) -> #N/A | W17: =E17 -> 0 | X17: =IF(F17="outdoors",0.7, IF(F17="indoors - good ventilation",0.7, IF(F17="indoors - enhanced ventilation",0.3,1))) -> 1 | Y17: =IF(G17="<15min",0.1, IF(G17="15min-1hr",0.2, IF(G17="1-4hr",0.6,1))) -> 1 | Z17: =IF(AND(D17="solid",OR(W17="medium",W17="high")),1,IF(AND(D17="liquid",OR(W17="very low",W17="low")),1,Y17)) -> 1 | AA17: =IF(H17="<1%",0.1, IF(H17="1-5%",0.2, IF(H17="5-25%",0.6,1))) -> 1 | AB17: =IF(J17="RPE90%",0.1, IF(J17="RPE95%",0.05,1)) -> 1 | AC17: =IF(K17="PPE80%",0.2, IF(K17="PPE90%",0.1, IF(AND(C17="prof",K17="PPE95%"),0.1, IF(K17="PPE95%",0.05,1)))) -> 1 | AD17: =IF(AND(AND(D17="liquid",W17="very low"),NOT(OR(B17="PROC7",B17="PROC11",B17="PROC17",B17="PROC18",AND(B17="PROC10",I17="no"),AND(B17="PROC19",I17="no")))),1,4) -> 4 | AE17: =CONCATENATE(B17,D17,I17,W17,C17) -> 0 | AF17: =IF(AND(D17="solid",E17="very low"),"n/a",IF(D17="solid",VLOOKUP(AE17,TRAlookup!$A$2:$H$729,2,FALSE),IFERROR(VLOOKUP(AE17,TRAlookup!$A$2:$H$729,2,FALSE)*$B$9/24,"n/a"))) -> n/a | AG17: =IF(AND(D17="solid",E17="very low"),"n/a",VLOOKUP(AE17,TRAlookup!$A$2:$H$729,3,FALSE)) -> #N/A | AH17: =IF(AND(D17="solid",E17="very low"),"n/a",VLOOKUP(AE17,TRAlookup!$A$2:$H$729,4,FALSE)) -> #N/A | AJ17: =IF(AND(D17="liquid",OR(AND(B17="PROC7",C17="ind"),AND(B17="PROC10",I17="no"),AND(B17="PROC11",C17="prof"),OR(B17="PROC17",B17="PROC18"),AND(B17="PROC19",I17="no"))),"Note that the TRA predicts vapour phase exposure; exposure by aerosols is not taken into account; if aerosol formation is relevant, refer to other information or models. ","") | AK17: =IF(AND(B17="PROC1",I17="yes"),"No reduction for LEV for PROC1. ","") | AL17: =IF(Z17>Y17,"No reduction for duration on dermal estimate. ","")
B18: PROC7 | C18: ind | D18: liquid | E18: very low | F18: indoors - no or basic ventilation | G18: >4hr | H18: >25% | I18: no | J18: no RPE | K18: no PPE | L18: no | M18: =IF(AF18="n/a","change input",IF(AND(F18="outdoors",I18="yes"),"change input",IF(AND(C18="prof",F18="indoors - enhanced ventilation",I18="yes"),"change input",AF18*X18*Y18*AA18*AB18*VLOOKUP(AE18,TRAlookup!$A$2:$H$729,5,FALSE)))) -> 0 | N18: =IF(OR(AG18="n/a",M18="change input"),"n/a",IF(L18="yes",AG18*Z18*AA18*AC18*VLOOKUP(AE18,TRAlookup!$A$2:$H$729,6,FALSE),AG18*Z18*AA18*AC18)) -> 42.86 | O18: =IF(OR(M18="n/a",M18="change input"),"n/a",M18*AD18/Y18) -> 0 | P18: =IF(OR(AG18="n/a",M18="change input"),"n/a",IF(L18="yes",AH18*Z18*AA18*AC18*VLOOKUP(AE18,TRAlookup!$A$2:$H$729,6,FALSE),AH18*Z18*AA18*AC18)) -> 2000 | Q18: =IF(OR(M18="n/a",M18="change input"),"n/a",M18/$G$6) -> #DIV/0! | R18: =IF(N18="n/a","n/a",N18/$G$7) -> #DIV/0! | S18: =IF(O18="n/a","n/a",O18/$G$8) -> #DIV/0! | T18: =IF(P18="n/a","n/a",P18/$G$9) -> #DIV/0! | U18: =IF(AND(D18="solid",E18="very low"),"Incorrect fugacity for solids.",IF(AF18="n/a",VLOOKUP(AE18,TRAlookup!$A$2:$H$729,8,FALSE),IF(AND(F18="outdoors",I18="yes"),"Combination 'outdoors' and 'LEV' not allowed. ",IF(AND(C18="prof",F18="indoors - enhanced ventilation",I18="yes"),"Combination 'indoors - enhanced ventilation' and 'LEV' not allowed for professional setting. ",CONCATENATE(AJ18,AK18,AL18))))) -> Note that the TRA predicts vapour phase exposure; exposure by aerosols is not taken into account; if aerosol formation is relevant, refer to other information or models. | W18: =E18 -> very low | X18: =IF(F18="outdoors",0.7, IF(F18="indoors - good ventilation",0.7, IF(F18="indoors - enhanced ventilation",0.3,1))) -> 1 | Y18: =IF(G18="<15min",0.1, IF(G18="15min-1hr",0.2, IF(G18="1-4hr",0.6,1))) -> 1 | Z18: =IF(AND(D18="solid",OR(W18="medium",W18="high")),1,IF(AND(D18="liquid",OR(W18="very low",W18="low")),1,Y18)) -> 1 | AA18: =IF(H18="<1%",0.1, IF(H18="1-5%",0.2, IF(H18="5-25%",0.6,1))) -> 1 | AB18: =IF(J18="RPE90%",0.1, IF(J18="RPE95%",0.05,1)) -> 1 | AC18: =IF(K18="PPE80%",0.2, IF(K18="PPE90%",0.1, IF(AND(C18="prof",K18="PPE95%"),0.1, IF(K18="PPE95%",0.05,1)))) -> 1 | AD18: =IF(AND(AND(D18="liquid",W18="very low"),NOT(OR(B18="PROC7",B18="PROC11",B18="PROC17",B18="PROC18",AND(B18="PROC10",I18="no"),AND(B18="PROC19",I18="no")))),1,4) -> 4 | AE18: =CONCATENATE(B18,D18,I18,W18,C18) -> PROC7liquidnovery lowind | AF18: =IF(AND(D18="solid",E18="very low"),"n/a",IF(D18="solid",VLOOKUP(AE18,TRAlookup!$A$2:$H$729,2,FALSE),IFERROR(VLOOKUP(AE18,TRAlookup!$A$2:$H$729,2,FALSE)*$B$9/24,"n/a"))) -> 0 | AG18: =IF(AND(D18="solid",E18="very low"),"n/a",VLOOKUP(AE18,TRAlookup!$A$2:$H$729,3,FALSE)) -> 42.86 | AH18: =IF(AND(D18="solid",E18="very low"),"n/a",VLOOKUP(AE18,TRAlookup!$A$2:$H$729,4,FALSE)) -> 2000 | AJ18: =IF(AND(D18="liquid",OR(AND(B18="PROC7",C18="ind"),AND(B18="PROC10",I18="no"),AND(B18="PROC11",C18="prof"),OR(B18="PROC17",B18="PROC18"),AND(B18="PROC19",I18="no"))),"Note that the TRA predicts vapour phase exposure; exposure by aerosols is not taken into account; if aerosol formation is relevant, refer to other information or models. ","") -> Note that the TRA predicts vapour phase exposure; exposure by aerosols is not taken into account; if aerosol formation is relevant, refer to other information or models. | AK18: =IF(AND(B18="PROC1",I18="yes"),"No reduction for LEV for PROC1. ","") | AL18: =IF(Z18>Y18,"No reduction for duration on dermal estimate. ","")
B19: PROC8a | C19: ind | D19: liquid | E19: very low | F19: indoors - no or basic ventilation | G19: >4hr | H19: >25% | I19: no | J19: no RPE | K19: no PPE | L19: no | M19: =IF(AF19="n/a","change input",IF(AND(F19="outdoors",I19="yes"),"change input",IF(AND(C19="prof",F19="indoors - enhanced ventilation",I19="yes"),"change input",AF19*X19*Y19*AA19*AB19*VLOOKUP(AE19,TRAlookup!$A$2:$H$729,5,FALSE)))) -> 0 | N19: =IF(OR(AG19="n/a",M19="change input"),"n/a",IF(L19="yes",AG19*Z19*AA19*AC19*VLOOKUP(AE19,TRAlookup!$A$2:$H$729,6,FALSE),AG19*Z19*AA19*AC19)) -> 27.43 | O19: =IF(OR(M19="n/a",M19="change input"),"n/a",M19*AD19/Y19) -> 0 | P19: =IF(OR(AG19="n/a",M19="change input"),"n/a",IF(L19="yes",AH19*Z19*AA19*AC19*VLOOKUP(AE19,TRAlookup!$A$2:$H$729,6,FALSE),AH19*Z19*AA19*AC19)) -> 2000 | Q19: =IF(OR(M19="n/a",M19="change input"),"n/a",M19/$G$6) -> #DIV/0! | R19: =IF(N19="n/a","n/a",N19/$G$7) -> #DIV/0! | S19: =IF(O19="n/a","n/a",O19/$G$8) -> #DIV/0! | T19: =IF(P19="n/a","n/a",P19/$G$9) -> #DIV/0! | U19: =IF(AND(D19="solid",E19="very low"),"Incorrect fugacity for solids.",IF(AF19="n/a",VLOOKUP(AE19,TRAlookup!$A$2:$H$729,8,FALSE),IF(AND(F19="outdoors",I19="yes"),"Combination 'outdoors' and 'LEV' not allowed. ",IF(AND(C19="prof",F19="indoors - enhanced ventilation",I19="yes"),"Combination 'indoors - enhanced ventilation' and 'LEV' not allowed for professional setting. ",CONCATENATE(AJ19,AK19,AL19))))) | W19: =E19 -> very low | X19: =IF(F19="outdoors",0.7, IF(F19="indoors - good ventilation",0.7, IF(F19="indoors - enhanced ventilation",0.3,1))) -> 1 | Y19: =IF(G19="<15min",0.1, IF(G19="15min-1hr",0.2, IF(G19="1-4hr",0.6,1))) -> 1 | Z19: =IF(AND(D19="solid",OR(W19="medium",W19="high")),1,IF(AND(D19="liquid",OR(W19="very low",W19="low")),1,Y19)) -> 1 | AA19: =IF(H19="<1%",0.1, IF(H19="1-5%",0.2, IF(H19="5-25%",0.6,1))) -> 1 | AB19: =IF(J19="RPE90%",0.1, IF(J19="RPE95%",0.05,1)) -> 1 | AC19: =IF(K19="PPE80%",0.2, IF(K19="PPE90%",0.1, IF(AND(C19="prof",K19="PPE95%"),0.1, IF(K19="PPE95%",0.05,1)))) -> 1 | AD19: =IF(AND(AND(D19="liquid",W19="very low"),NOT(OR(B19="PROC7",B19="PROC11",B19="PROC17",B19="PROC18",AND(B19="PROC10",I19="no"),AND(B19="PROC19",I19="no")))),1,4) -> 1 | AE19: =CONCATENATE(B19,D19,I19,W19,C19) -> PROC8aliquidnovery lowind | AF19: =IF(AND(D19="solid",E19="very low"),"n/a",IF(D19="solid",VLOOKUP(AE19,TRAlookup!$A$2:$H$729,2,FALSE),IFERROR(VLOOKUP(AE19,TRAlookup!$A$2:$H$729,2,FALSE)*$B$9/24,"n/a"))) -> 0 | AG19: =IF(AND(D19="solid",E19="very low"),"n/a",VLOOKUP(AE19,TRAlookup!$A$2:$H$729,3,FALSE)) -> 27.43 | AH19: =IF(AND(D19="solid",E19="very low"),"n/a",VLOOKUP(AE19,TRAlookup!$A$2:$H$729,4,FALSE)) -> 2000 | AJ19: =IF(AND(D19="liquid",OR(AND(B19="PROC7",C19="ind"),AND(B19="PROC10",I19="no"),AND(B19="PROC11",C19="prof"),OR(B19="PROC17",B19="PROC18"),AND(B19="PROC19",I19="no"))),"Note that the TRA predicts vapour phase exposure; exposure by aerosols is not taken into account; if aerosol formation is relevant, refer to other information or models. ","") | AK19: =IF(AND(B19="PROC1",I19="yes"),"No reduction for LEV for PROC1. ","") | AL19: =IF(Z19>Y19,"No reduction for duration on dermal estimate. ","")
B20: PROC8b | C20: ind | D20: liquid | E20: very low | F20: indoors - no or basic ventilation | G20: >4hr | H20: >25% | I20: no | J20: no RPE | K20: no PPE | L20: no | M20: =IF(AF20="n/a","change input",IF(AND(F20="outdoors",I20="yes"),"change input",IF(AND(C20="prof",F20="indoors - enhanced ventilation",I20="yes"),"change input",AF20*X20*Y20*AA20*AB20*VLOOKUP(AE20,TRAlookup!$A$2:$H$729,5,FALSE)))) -> 0 | N20: =IF(OR(AG20="n/a",M20="change input"),"n/a",IF(L20="yes",AG20*Z20*AA20*AC20*VLOOKUP(AE20,TRAlookup!$A$2:$H$729,6,FALSE),AG20*Z20*AA20*AC20)) -> 13.71 | O20: =IF(OR(M20="n/a",M20="change input"),"n/a",M20*AD20/Y20) -> 0 | P20: =IF(OR(AG20="n/a",M20="change input"),"n/a",IF(L20="yes",AH20*Z20*AA20*AC20*VLOOKUP(AE20,TRAlookup!$A$2:$H$729,6,FALSE),AH20*Z20*AA20*AC20)) -> 1000 | Q20: =IF(OR(M20="n/a",M20="change input"),"n/a",M20/$G$6) -> #DIV/0! | R20: =IF(N20="n/a","n/a",N20/$G$7) -> #DIV/0! | S20: =IF(O20="n/a","n/a",O20/$G$8) -> #DIV/0! | T20: =IF(P20="n/a","n/a",P20/$G$9) -> #DIV/0! | U20: =IF(AND(D20="solid",E20="very low"),"Incorrect fugacity for solids.",IF(AF20="n/a",VLOOKUP(AE20,TRAlookup!$A$2:$H$729,8,FALSE),IF(AND(F20="outdoors",I20="yes"),"Combination 'outdoors' and 'LEV' not allowed. ",IF(AND(C20="prof",F20="indoors - enhanced ventilation",I20="yes"),"Combination 'indoors - enhanced ventilation' and 'LEV' not allowed for professional setting. ",CONCATENATE(AJ20,AK20,AL20))))) | W20: =E20 -> very low | X20: =IF(F20="outdoors",0.7, IF(F20="indoors - good ventilation",0.7, IF(F20="indoors - enhanced ventilation",0.3,1))) -> 1 | Y20: =IF(G20="<15min",0.1, IF(G20="15min-1hr",0.2, IF(G20="1-4hr",0.6,1))) -> 1 | Z20: =IF(AND(D20="solid",OR(W20="medium",W20="high")),1,IF(AND(D20="liquid",OR(W20="very low",W20="low")),1,Y20)) -> 1 | AA20: =IF(H20="<1%",0.1, IF(H20="1-5%",0.2, IF(H20="5-25%",0.6,1))) -> 1 | AB20: =IF(J20="RPE90%",0.1, IF(J20="RPE95%",0.05,1)) -> 1 | AC20: =IF(K20="PPE80%",0.2, IF(K20="PPE90%",0.1, IF(AND(C20="prof",K20="PPE95%"),0.1, IF(K20="PPE95%",0.05,1)))) -> 1 | AD20: =IF(AND(AND(D20="liquid",W20="very low"),NOT(OR(B20="PROC7",B20="PROC11",B20="PROC17",B20="PROC18",AND(B20="PROC10",I20="no"),AND(B20="PROC19",I20="no")))),1,4) -> 1 | AE20: =CONCATENATE(B20,D20,I20,W20,C20) -> PROC8bliquidnovery lowind | AF20: =IF(AND(D20="solid",E20="very low"),"n/a",IF(D20="solid",VLOOKUP(AE20,TRAlookup!$A$2:$H$729,2,FALSE),IFERROR(VLOOKUP(AE20,TRAlookup!$A$2:$H$729,2,FALSE)*$B$9/24,"n/a"))) -> 0 | AG20: =IF(AND(D20="solid",E20="very low"),"n/a",VLOOKUP(AE20,TRAlookup!$A$2:$H$729,3,FALSE)) -> 13.71 | AH20: =IF(AND(D20="solid",E20="very low"),"n/a",VLOOKUP(AE20,TRAlookup!$A$2:$H$729,4,FALSE)) -> 1000 | AJ20: =IF(AND(D20="liquid",OR(AND(B20="PROC7",C20="ind"),AND(B20="PROC10",I20="no"),AND(B20="PROC11",C20="prof"),OR(B20="PROC17",B20="PROC18"),AND(B20="PROC19",I20="no"))),"Note that the TRA predicts vapour phase exposure; exposure by aerosols is not taken into account; if aerosol formation is relevant, refer to other information or models. ","") | AK20: =IF(AND(B20="PROC1",I20="yes"),"No reduction for LEV for PROC1. ","") | AL20: =IF(Z20>Y20,"No reduction for duration on dermal estimate. ","")
B21: PROC9 | C21: ind | D21: liquid | E21: very low | F21: indoors - no or basic ventilation | G21: >4hr | H21: >25% | I21: no | J21: no RPE | K21: no PPE | L21: no | M21: =IF(AF21="n/a","change input",IF(AND(F21="outdoors",I21="yes"),"change input",IF(AND(C21="prof",F21="indoors - enhanced ventilation",I21="yes"),"change input",AF21*X21*Y21*AA21*AB21*VLOOKUP(AE21,TRAlookup!$A$2:$H$729,5,FALSE)))) -> 0 | N21: =IF(OR(AG21="n/a",M21="change input"),"n/a",IF(L21="yes",AG21*Z21*AA21*AC21*VLOOKUP(AE21,TRAlookup!$A$2:$H$729,6,FALSE),AG21*Z21*AA21*AC21)) -> 6.86 | O21: =IF(OR(M21="n/a",M21="change input"),"n/a",M21*AD21/Y21) -> 0 | P21: =IF(OR(AG21="n/a",M21="change input"),"n/a",IF(L21="yes",AH21*Z21*AA21*AC21*VLOOKUP(AE21,TRAlookup!$A$2:$H$729,6,FALSE),AH21*Z21*AA21*AC21)) -> 1000 | Q21: =IF(OR(M21="n/a",M21="change input"),"n/a",M21/$G$6) -> #DIV/0! | R21: =IF(N21="n/a","n/a",N21/$G$7) -> #DIV/0! | S21: =IF(O21="n/a","n/a",O21/$G$8) -> #DIV/0! | T21: =IF(P21="n/a","n/a",P21/$G$9) -> #DIV/0! | U21: =IF(AND(D21="solid",E21="very low"),"Incorrect fugacity for solids.",IF(AF21="n/a",VLOOKUP(AE21,TRAlookup!$A$2:$H$729,8,FALSE),IF(AND(F21="outdoors",I21="yes"),"Combination 'outdoors' and 'LEV' not allowed. ",IF(AND(C21="prof",F21="indoors - enhanced ventilation",I21="yes"),"Combination 'indoors - enhanced ventilation' and 'LEV' not allowed for professional setting. ",CONCATENATE(AJ21,AK21,AL21))))) | W21: =E21 -> very low | X21: =IF(F21="outdoors",0.7, IF(F21="indoors - good ventilation",0.7, IF(F21="indoors - enhanced ventilation",0.3,1))) -> 1 | Y21: =IF(G21="<15min",0.1, IF(G21="15min-1hr",0.2, IF(G21="1-4hr",0.6,1))) -> 1 | Z21: =IF(AND(D21="solid",OR(W21="medium",W21="high")),1,IF(AND(D21="liquid",OR(W21="very low",W21="low")),1,Y21)) -> 1 | AA21: =IF(H21="<1%",0.1, IF(H21="1-5%",0.2, IF(H21="5-25%",0.6,1))) -> 1 | AB21: =IF(J21="RPE90%",0.1, IF(J21="RPE95%",0.05,1)) -> 1 | AC21: =IF(K21="PPE80%",0.2, IF(K21="PPE90%",0.1, IF(AND(C21="prof",K21="PPE95%"),0.1, IF(K21="PPE95%",0.05,1)))) -> 1 | AD21: =IF(AND(AND(D21="liquid",W21="very low"),NOT(OR(B21="PROC7",B21="PROC11",B21="PROC17",B21="PROC18",AND(B21="PROC10",I21="no"),AND(B21="PROC19",I21="no")))),1,4) -> 1 | AE21: =CONCATENATE(B21,D21,I21,W21,C21) -> PROC9liquidnovery lowind | AF21: =IF(AND(D21="solid",E21="very low"),"n/a",IF(D21="solid",VLOOKUP(AE21,TRAlookup!$A$2:$H$729,2,FALSE),IFERROR(VLOOKUP(AE21,TRAlookup!$A$2:$H$729,2,FALSE)*$B$9/24,"n/a"))) -> 0 | AG21: =IF(AND(D21="solid",E21="very low"),"n/a",VLOOKUP(AE21,TRAlookup!$A$2:$H$729,3,FALSE)) -> 6.86 | AH21: =IF(AND(D21="solid",E21="very low"),"n/a",VLOOKUP(AE21,TRAlookup!$A$2:$H$729,4,FALSE)) -> 1000 | AJ21: =IF(AND(D21="liquid",OR(AND(B21="PROC7",C21="ind"),AND(B21="PROC10",I21="no"),AND(B21="PROC11",C21="prof"),OR(B21="PROC17",B21="PROC18"),AND(B21="PROC19",I21="no"))),"Note that the TRA predicts vapour phase exposure; exposure by aerosols is not taken into account; if aerosol formation is relevant, refer to other information or models. ","") | AK21: =IF(AND(B21="PROC1",I21="yes"),"No reduction for LEV for PROC1. ","") | AL21: =IF(Z21>Y21,"No reduction for duration on dermal estimate. ","")
B22: PROC10 | C22: ind | D22: liquid | E22: very low | F22: indoors - no or basic ventilation | G22: >4hr | H22: >25% | I22: no | J22: no RPE | K22: no PPE | L22: no | M22: =IF(AF22="n/a","change input",IF(AND(F22="outdoors",I22="yes"),"change input",IF(AND(C22="prof",F22="indoors - enhanced ventilation",I22="yes"),"change input",AF22*X22*Y22*AA22*AB22*VLOOKUP(AE22,TRAlookup!$A$2:$H$729,5,FALSE)))) -> 0 | N22: =IF(OR(AG22="n/a",M22="change input"),"n/a",IF(L22="yes",AG22*Z22*AA22*AC22*VLOOKUP(AE22,TRAlookup!$A$2:$H$729,6,FALSE),AG22*Z22*AA22*AC22)) -> 27.43 | O22: =IF(OR(M22="n/a",M22="change input"),"n/a",M22*AD22/Y22) -> 0 | P22: =IF(OR(AG22="n/a",M22="change input"),"n/a",IF(L22="yes",AH22*Z22*AA22*AC22*VLOOKUP(AE22,TRAlookup!$A$2:$H$729,6,FALSE),AH22*Z22*AA22*AC22)) -> 2000 | Q22: =IF(OR(M22="n/a",M22="change input"),"n/a",M22/$G$6) -> #DIV/0! | R22: =IF(N22="n/a","n/a",N22/$G$7) -> #DIV/0! | S22: =IF(O22="n/a","n/a",O22/$G$8) -> #DIV/0! | T22: =IF(P22="n/a","n/a",P22/$G$9) -> #DIV/0! | U22: =IF(AND(D22="solid",E22="very low"),"Incorrect fugacity for solids.",IF(AF22="n/a",VLOOKUP(AE22,TRAlookup!$A$2:$H$729,8,FALSE),IF(AND(F22="outdoors",I22="yes"),"Combination 'outdoors' and 'LEV' not allowed. ",IF(AND(C22="prof",F22="indoors - enhanced ventilation",I22="yes"),"Combination 'indoors - enhanced ventilation' and 'LEV' not allowed for professional setting. ",CONCATENATE(AJ22,AK22,AL22))))) -> Note that the TRA predicts vapour phase exposure; exposure by aerosols is not taken into account; if aerosol formation is relevant, refer to other information or models. | W22: =E22 -> very low | X22: =IF(F22="outdoors",0.7, IF(F22="indoors - good ventilation",0.7, IF(F22="indoors - enhanced ventilation",0.3,1))) -> 1 | Y22: =IF(G22="<15min",0.1, IF(G22="15min-1hr",0.2, IF(G22="1-4hr",0.6,1))) -> 1 | Z22: =IF(AND(D22="solid",OR(W22="medium",W22="high")),1,IF(AND(D22="liquid",OR(W22="very low",W22="low")),1,Y22)) -> 1 | AA22: =IF(H22="<1%",0.1, IF(H22="1-5%",0.2, IF(H22="5-25%",0.6,1))) -> 1 | AB22: =IF(J22="RPE90%",0.1, IF(J22="RPE95%",0.05,1)) -> 1 | AC22: =IF(K22="PPE80%",0.2, IF(K22="PPE90%",0.1, IF(AND(C22="prof",K22="PPE95%"),0.1, IF(K22="PPE95%",0.05,1)))) -> 1 | AD22: =IF(AND(AND(D22="liquid",W22="very low"),NOT(OR(B22="PROC7",B22="PROC11",B22="PROC17",B22="PROC18",AND(B22="PROC10",I22="no"),AND(B22="PROC19",I22="no")))),1,4) -> 4 | AE22: =CONCATENATE(B22,D22,I22,W22,C22) -> PROC10liquidnovery lowind | AF22: =IF(AND(D22="solid",E22="very low"),"n/a",IF(D22="solid",VLOOKUP(AE22,TRAlookup!$A$2:$H$729,2,FALSE),IFERROR(VLOOKUP(AE22,TRAlookup!$A$2:$H$729,2,FALSE)*$B$9/24,"n/a"))) -> 0 | AG22: =IF(AND(D22="solid",E22="very low"),"n/a",VLOOKUP(AE22,TRAlookup!$A$2:$H$729,3,FALSE)) -> 27.43 | AH22: =IF(AND(D22="solid",E22="very low"),"n/a",VLOOKUP(AE22,TRAlookup!$A$2:$H$729,4,FALSE)) -> 2000 | AJ22: =IF(AND(D22="liquid",OR(AND(B22="PROC7",C22="ind"),AND(B22="PROC10",I22="no"),AND(B22="PROC11",C22="prof"),OR(B22="PROC17",B22="PROC18"),AND(B22="PROC19",I22="no"))),"Note that the TRA predicts vapour phase exposure; exposure by aerosols is not taken into account; if aerosol formation is relevant, refer to other information or models. ","") -> Note that the TRA predicts vapour phase exposure; exposure by aerosols is not taken into account; if aerosol formation is relevant, refer to other information or models. | AK22: =IF(AND(B22="PROC1",I22="yes"),"No reduction for LEV for PROC1. ","") | AL22: =IF(Z22>Y22,"No reduction for duration on dermal estimate. ","")
B23: PROC11 | C23: prof | D23: liquid | E23: very low | F23: indoors - no or basic ventilation | G23: >4hr | H23: >25% | I23: no | J23: no RPE | K23: no PPE | L23: no | M23: =IF(AF23="n/a","change input",IF(AND(F23="outdoors",I23="yes"),"change input",IF(AND(C23="prof",F23="indoors - enhanced ventilation",I23="yes"),"change input",AF23*X23*Y23*AA23*AB23*VLOOKUP(AE23,TRAlookup!$A$2:$H$729,5,FALSE)))) -> 0 | N23: =IF(OR(AG23="n/a",M23="change input"),"n/a",IF(L23="yes",AG23*Z23*AA23*AC23*VLOOKUP(AE23,TRAlookup!$A$2:$H$729,6,FALSE),AG23*Z23*AA23*AC23)) -> 107.14 | O23: =IF(OR(M23="n/a",M23="change input"),"n/a",M23*AD23/Y23) -> 0 | P23: =IF(OR(AG23="n/a",M23="change input"),"n/a",IF(L23="yes",AH23*Z23*AA23*AC23*VLOOKUP(AE23,TRAlookup!$A$2:$H$729,6,FALSE),AH23*Z23*AA23*AC23)) -> 5000 | Q23: =IF(OR(M23="n/a",M23="change input"),"n/a",M23/$G$6) -> #DIV/0! | R23: =IF(N23="n/a","n/a",N23/$G$7) -> #DIV/0! | S23: =IF(O23="n/a","n/a",O23/$G$8) -> #DIV/0! | T23: =IF(P23="n/a","n/a",P23/$G$9) -> #DIV/0! | U23: =IF(AND(D23="solid",E23="very low"),"Incorrect fugacity for solids.",IF(AF23="n/a",VLOOKUP(AE23,TRAlookup!$A$2:$H$729,8,FALSE),IF(AND(F23="outdoors",I23="yes"),"Combination 'outdoors' and 'LEV' not allowed. ",IF(AND(C23="prof",F23="indoors - enhanced ventilation",I23="yes"),"Combination 'indoors - enhanced ventilation' and 'LEV' not allowed for professional setting. ",CONCATENATE(AJ23,AK23,AL23))))) -> Note that the TRA predicts vapour phase exposure; exposure by aerosols is not taken into account; if aerosol formation is relevant, refer to other information or models. | W23: =E23 -> very low | X23: =IF(F23="outdoors",0.7, IF(F23="indoors - good ventilation",0.7, IF(F23="indoors - enhanced ventilation",0.3,1))) -> 1 | Y23: =IF(G23="<15min",0.1, IF(G23="15min-1hr",0.2, IF(G23="1-4hr",0.6,1))) -> 1 | Z23: =IF(AND(D23="solid",OR(W23="medium",W23="high")),1,IF(AND(D23="liquid",OR(W23="very low",W23="low")),1,Y23)) -> 1 | AA23: =IF(H23="<1%",0.1, IF(H23="1-5%",0.2, IF(H23="5-25%",0.6,1))) -> 1 | AB23: =IF(J23="RPE90%",0.1, IF(J23="RPE95%",0.05,1)) -> 1 | AC23: =IF(K23="PPE80%",0.2, IF(K23="PPE90%",0.1, IF(AND(C23="prof",K23="PPE95%"),0.1, IF(K23="PPE95%",0.05,1)))) -> 1 | AD23: =IF(AND(AND(D23="liquid",W23="very low"),NOT(OR(B23="PROC7",B23="PROC11",B23="PROC17",B23="PROC18",AND(B23="PROC10",I23="no"),AND(B23="PROC19",I23="no")))),1,4) -> 4 | AE23: =CONCATENATE(B23,D23,I23,W23,C23) -> PROC11liquidnovery lowprof | AF23: =IF(AND(D23="solid",E23="very low"),"n/a",IF(D23="solid",VLOOKUP(AE23,TRAlookup!$A$2:$H$729,2,FALSE),IFERROR(VLOOKUP(AE23,TRAlookup!$A$2:$H$729,2,FALSE)*$B$9/24,"n/a"))) -> 0 | AG23: =IF(AND(D23="solid",E23="very low"),"n/a",VLOOKUP(AE23,TRAlookup!$A$2:$H$729,3,FALSE)) -> 107.14 | AH23: =IF(AND(D23="solid",E23="very low"),"n/a",VLOOKUP(AE23,TRAlookup!$A$2:$H$729,4,FALSE)) -> 5000 | AJ23: =IF(AND(D23="liquid",OR(AND(B23="PROC7",C23="ind"),AND(B23="PROC10",I23="no"),AND(B23="PROC11",C23="prof"),OR(B23="PROC17",B23="PROC18"),AND(B23="PROC19",I23="no"))),"Note that the TRA predicts vapour phase exposure; exposure by aerosols is not taken into account; if aerosol formation is relevant, refer to other information or models. ","") -> Note that the TRA predicts vapour phase exposure; exposure by aerosols is not taken into account; if aerosol formation is relevant, refer to other information or models. | AK23: =IF(AND(B23="PROC1",I23="yes"),"No reduction for LEV for PROC1. ","") | AL23: =IF(Z23>Y23,"No reduction for duration on dermal estimate. ","")
B24: PROC12 | C24: ind | D24: liquid | E24: very low | F24: indoors - no or basic ventilation | G24: >4hr | H24: >25% | I24: no | J24: no RPE | K24: no PPE | L24: no | M24: =IF(AF24="n/a","change input",IF(AND(F24="outdoors",I24="yes"),"change input",IF(AND(C24="prof",F24="indoors - enhanced ventilation",I24="yes"),"change input",AF24*X24*Y24*AA24*AB24*VLOOKUP(AE24,TRAlookup!$A$2:$H$729,5,FALSE)))) -> 0 | N24: =IF(OR(AG24="n/a",M24="change input"),"n/a",IF(L24="yes",AG24*Z24*AA24*AC24*VLOOKUP(AE24,TRAlookup!$A$2:$H$729,6,FALSE),AG24*Z24*AA24*AC24)) -> 0.34 | O24: =IF(OR(M24="n/a",M24="change input"),"n/a",M24*AD24/Y24) -> 0 | P24: =IF(OR(AG24="n/a",M24="change input"),"n/a",IF(L24="yes",AH24*Z24*AA24*AC24*VLOOKUP(AE24,TRAlookup!$A$2:$H$729,6,FALSE),AH24*Z24*AA24*AC24)) -> 100 | Q24: =IF(OR(M24="n/a",M24="change input"),"n/a",M24/$G$6) -> #DIV/0! | R24: =IF(N24="n/a","n/a",N24/$G$7) -> #DIV/0! | S24: =IF(O24="n/a","n/a",O24/$G$8) -> #DIV/0! | T24: =IF(P24="n/a","n/a",P24/$G$9) -> #DIV/0! | U24: =IF(AND(D24="solid",E24="very low"),"Incorrect fugacity for solids.",IF(AF24="n/a",VLOOKUP(AE24,TRAlookup!$A$2:$H$729,8,FALSE),IF(AND(F24="outdoors",I24="yes"),"Combination 'outdoors' and 'LEV' not allowed. ",IF(AND(C24="prof",F24="indoors - enhanced ventilation",I24="yes"),"Combination 'indoors - enhanced ventilation' and 'LEV' not allowed for professional setting. ",CONCATENATE(AJ24,AK24,AL24))))) | W24: =E24 -> very low | X24: =IF(F24="outdoors",0.7, IF(F24="indoors - good ventilation",0.7, IF(F24="indoors - enhanced ventilation",0.3,1))) -> 1 | Y24: =IF(G24="<15min",0.1, IF(G24="15min-1hr",0.2, IF(G24="1-4hr",0.6,1))) -> 1 | Z24: =IF(AND(D24="solid",OR(W24="medium",W24="high")),1,IF(AND(D24="liquid",OR(W24="very low",W24="low")),1,Y24)) -> 1 | AA24: =IF(H24="<1%",0.1, IF(H24="1-5%",0.2, IF(H24="5-25%",0.6,1))) -> 1 | AB24: =IF(J24="RPE90%",0.1, IF(J24="RPE95%",0.05,1)) -> 1 | AC24: =IF(K24="PPE80%",0.2, IF(K24="PPE90%",0.1, IF(AND(C24="prof",K24="PPE95%"),0.1, IF(K24="PPE95%",0.05,1)))) -> 1 | AD24: =IF(AND(AND(D24="liquid",W24="very low"),NOT(OR(B24="PROC7",B24="PROC11",B24="PROC17",B24="PROC18",AND(B24="PROC10",I24="no"),AND(B24="PROC19",I24="no")))),1,4) -> 1 | AE24: =CONCATENATE(B24,D24,I24,W24,C24) -> PROC12liquidnovery lowind | AF24: =IF(AND(D24="solid",E24="very low"),"n/a",IF(D24="solid",VLOOKUP(AE24,TRAlookup!$A$2:$H$729,2,FALSE),IFERROR(VLOOKUP(AE24,TRAlookup!$A$2:$H$729,2,FALSE)*$B$9/24,"n/a"))) -> 0 | AG24: =IF(AND(D24="solid",E24="very low"),"n/a",VLOOKUP(AE24,TRAlookup!$A$2:$H$729,3,FALSE)) -> 0.34 | AH24: =IF(AND(D24="solid",E24="very low"),"n/a",VLOOKUP(AE24,TRAlookup!$A$2:$H$729,4,FALSE)) -> 100 | AJ24: =IF(AND(D24="liquid",OR(AND(B24="PROC7",C24="ind"),AND(B24="PROC10",I24="no"),AND(B24="PROC11",C24="prof"),OR(B24="PROC17",B24="PROC18"),AND(B24="PROC19",I24="no"))),"Note that the TRA predicts vapour phase exposure; exposure by aerosols is not taken into account; if aerosol formation is relevant, refer to other information or models. ","") | AK24: =IF(AND(B24="PROC1",I24="yes"),"No reduction for LEV for PROC1. ","") | AL24: =IF(Z24>Y24,"No reduction for duration on dermal estimate. ","")
B25: PROC13 | C25: ind | D25: liquid | E25: very low | F25: indoors - no or basic ventilation | G25: >4hr | H25: >25% | I25: no | J25: no RPE | K25: no PPE | L25: no | M25: =IF(AF25="n/a","change input",IF(AND(F25="outdoors",I25="yes"),"change input",IF(AND(C25="prof",F25="indoors - enhanced ventilation",I25="yes"),"change input",AF25*X25*Y25*AA25*AB25*VLOOKUP(AE25,TRAlookup!$A$2:$H$729,5,FALSE)))) -> 0 | N25: =IF(OR(AG25="n/a",M25="change input"),"n/a",IF(L25="yes",AG25*Z25*AA25*AC25*VLOOKUP(AE25,TRAlookup!$A$2:$H$729,6,FALSE),AG25*Z25*AA25*AC25)) -> 13.71 | O25: =IF(OR(M25="n/a",M25="change input"),"n/a",M25*AD25/Y25) -> 0 | P25: =IF(OR(AG25="n/a",M25="change input"),"n/a",IF(L25="yes",AH25*Z25*AA25*AC25*VLOOKUP(AE25,TRAlookup!$A$2:$H$729,6,FALSE),AH25*Z25*AA25*AC25)) -> 2000 | Q25: =IF(OR(M25="n/a",M25="change input"),"n/a",M25/$G$6) -> #DIV/0! | R25: =IF(N25="n/a","n/a",N25/$G$7) -> #DIV/0! | S25: =IF(O25="n/a","n/a",O25/$G$8) -> #DIV/0! | T25: =IF(P25="n/a","n/a",P25/$G$9) -> #DIV/0! | U25: =IF(AND(D25="solid",E25="very low"),"Incorrect fugacity for solids.",IF(AF25="n/a",VLOOKUP(AE25,TRAlookup!$A$2:$H$729,8,FALSE),IF(AND(F25="outdoors",I25="yes"),"Combination 'outdoors' and 'LEV' not allowed. ",IF(AND(C25="prof",F25="indoors - enhanced ventilation",I25="yes"),"Combination 'indoors - enhanced ventilation' and 'LEV' not allowed for professional setting. ",CONCATENATE(AJ25,AK25,AL25))))) | W25: =E25 -> very low | X25: =IF(F25="outdoors",0.7, IF(F25="indoors - good ventilation",0.7, IF(F25="indoors - enhanced ventilation",0.3,1))) -> 1 | Y25: =IF(G25="<15min",0.1, IF(G25="15min-1hr",0.2, IF(G25="1-4hr",0.6,1))) -> 1 | Z25: =IF(AND(D25="solid",OR(W25="medium",W25="high")),1,IF(AND(D25="liquid",OR(W25="very low",W25="low")),1,Y25)) -> 1 | AA25: =IF(H25="<1%",0.1, IF(H25="1-5%",0.2, IF(H25="5-25%",0.6,1))) -> 1 | AB25: =IF(J25="RPE90%",0.1, IF(J25="RPE95%",0.05,1)) -> 1 | AC25: =IF(K25="PPE80%",0.2, IF(K25="PPE90%",0.1, IF(AND(C25="prof",K25="PPE95%"),0.1, IF(K25="PPE95%",0.05,1)))) -> 1 | AD25: =IF(AND(AND(D25="liquid",W25="very low"),NOT(OR(B25="PROC7",B25="PROC11",B25="PROC17",B25="PROC18",AND(B25="PROC10",I25="no"),AND(B25="PROC19",I25="no")))),1,4) -> 1 | AE25: =CONCATENATE(B25,D25,I25,W25,C25) -> PROC13liquidnovery lowind | AF25: =IF(AND(D25="solid",E25="very low"),"n/a",IF(D25="solid",VLOOKUP(AE25,TRAlookup!$A$2:$H$729,2,FALSE),IFERROR(VLOOKUP(AE25,TRAlookup!$A$2:$H$729,2,FALSE)*$B$9/24,"n/a"))) -> 0 | AG25: =IF(AND(D25="solid",E25="very low"),"n/a",VLOOKUP(AE25,TRAlookup!$A$2:$H$729,3,FALSE)) -> 13.71 | AH25: =IF(AND(D25="solid",E25="very low"),"n/a",VLOOKUP(AE25,TRAlookup!$A$2:$H$729,4,FALSE)) -> 2000 | AJ25: =IF(AND(D25="liquid",OR(AND(B25="PROC7",C25="ind"),AND(B25="PROC10",I25="no"),AND(B25="PROC11",C25="prof"),OR(B25="PROC17",B25="PROC18"),AND(B25="PROC19",I25="no"))),"Note that the TRA predicts vapour phase exposure; exposure by aerosols is not taken into account; if aerosol formation is relevant, refer to other information or models. ","") | AK25: =IF(AND(B25="PROC1",I25="yes"),"No reduction for LEV for PROC1. ","") | AL25: =IF(Z25>Y25,"No reduction for duration on dermal estimate. ","")
B26: PROC14 | C26: ind | D26: liquid | E26: very low | F26: indoors - no or basic ventilation | G26: >4hr | H26: >25% | I26: no | J26: no RPE | K26: no PPE | L26: no | M26: =IF(AF26="n/a","change input",IF(AND(F26="outdoors",I26="yes"),"change input",IF(AND(C26="prof",F26="indoors - enhanced ventilation",I26="yes"),"change input",AF26*X26*Y26*AA26*AB26*VLOOKUP(AE26,TRAlookup!$A$2:$H$729,5,FALSE)))) -> 0 | N26: =IF(OR(AG26="n/a",M26="change input"),"n/a",IF(L26="yes",AG26*Z26*AA26*AC26*VLOOKUP(AE26,TRAlookup!$A$2:$H$729,6,FALSE),AG26*Z26*AA26*AC26)) -> 3.43 | O26: =IF(OR(M26="n/a",M26="change input"),"n/a",M26*AD26/Y26) -> 0 | P26: =IF(OR(AG26="n/a",M26="change input"),"n/a",IF(L26="yes",AH26*Z26*AA26*AC26*VLOOKUP(AE26,TRAlookup!$A$2:$H$729,6,FALSE),AH26*Z26*AA26*AC26)) -> 500 | Q26: =IF(OR(M26="n/a",M26="change input"),"n/a",M26/$G$6) -> #DIV/0! | R26: =IF(N26="n/a","n/a",N26/$G$7) -> #DIV/0! | S26: =IF(O26="n/a","n/a",O26/$G$8) -> #DIV/0! | T26: =IF(P26="n/a","n/a",P26/$G$9) -> #DIV/0! | U26: =IF(AND(D26="solid",E26="very low"),"Incorrect fugacity for solids.",IF(AF26="n/a",VLOOKUP(AE26,TRAlookup!$A$2:$H$729,8,FALSE),IF(AND(F26="outdoors",I26="yes"),"Combination 'outdoors' and 'LEV' not allowed. ",IF(AND(C26="prof",F26="indoors - enhanced ventilation",I26="yes"),"Combination 'indoors - enhanced ventilation' and 'LEV' not allowed for professional setting. ",CONCATENATE(AJ26,AK26,AL26))))) | W26: =E26 -> very low | X26: =IF(F26="outdoors",0.7, IF(F26="indoors - good ventilation",0.7, IF(F26="indoors - enhanced ventilation",0.3,1))) -> 1 | Y26: =IF(G26="<15min",0.1, IF(G26="15min-1hr",0.2, IF(G26="1-4hr",0.6,1))) -> 1 | Z26: =IF(AND(D26="solid",OR(W26="medium",W26="high")),1,IF(AND(D26="liquid",OR(W26="very low",W26="low")),1,Y26)) -> 1 | AA26: =IF(H26="<1%",0.1, IF(H26="1-5%",0.2, IF(H26="5-25%",0.6,1))) -> 1 | AB26: =IF(J26="RPE90%",0.1, IF(J26="RPE95%",0.05,1)) -> 1 | AC26: =IF(K26="PPE80%",0.2, IF(K26="PPE90%",0.1, IF(AND(C26="prof",K26="PPE95%"),0.1, IF(K26="PPE95%",0.05,1)))) -> 1 | AD26: =IF(AND(AND(D26="liquid",W26="very low"),NOT(OR(B26="PROC7",B26="PROC11",B26="PROC17",B26="PROC18",AND(B26="PROC10",I26="no"),AND(B26="PROC19",I26="no")))),1,4) -> 1 | AE26: =CONCATENATE(B26,D26,I26,W26,C26) -> PROC14liquidnovery lowind | AF26: =IF(AND(D26="solid",E26="very low"),"n/a",IF(D26="solid",VLOOKUP(AE26,TRAlookup!$A$2:$H$729,2,FALSE),IFERROR(VLOOKUP(AE26,TRAlookup!$A$2:$H$729,2,FALSE)*$B$9/24,"n/a"))) -> 0 | AG26: =IF(AND(D26="solid",E26="very low"),"n/a",VLOOKUP(AE26,TRAlookup!$A$2:$H$729,3,FALSE)) -> 3.43 | AH26: =IF(AND(D26="solid",E26="very low"),"n/a",VLOOKUP(AE26,TRAlookup!$A$2:$H$729,4,FALSE)) -> 500 | AJ26: =IF(AND(D26="liquid",OR(AND(B26="PROC7",C26="ind"),AND(B26="PROC10",I26="no"),AND(B26="PROC11",C26="prof"),OR(B26="PROC17",B26="PROC18"),AND(B26="PROC19",I26="no"))),"Note that the TRA predicts vapour phase exposure; exposure by aerosols is not taken into account; if aerosol formation is relevant, refer to other information or models. ","") | AK26: =IF(AND(B26="PROC1",I26="yes"),"No reduction for LEV for PROC1. ","") | AL26: =IF(Z26>Y26,"No reduction for duration on dermal estimate. ","")
B27: PROC15 | C27: ind | D27: liquid | E27: very low | F27: indoors - no or basic ventilation | G27: >4hr | H27: >25% | I27: no | J27: no RPE | K27: no PPE | L27: no | M27: =IF(AF27="n/a","change input",IF(AND(F27="outdoors",I27="yes"),"change input",IF(AND(C27="prof",F27="indoors - enhanced ventilation",I27="yes"),"change input",AF27*X27*Y27*AA27*AB27*VLOOKUP(AE27,TRAlookup!$A$2:$H$729,5,FALSE)))) -> 0 | N27: =IF(OR(AG27="n/a",M27="change input"),"n/a",IF(L27="yes",AG27*Z27*AA27*AC27*VLOOKUP(AE27,TRAlookup!$A$2:$H$729,6,FALSE),AG27*Z27*AA27*AC27)) -> 0.34 | O27: =IF(OR(M27="n/a",M27="change input"),"n/a",M27*AD27/Y27) -> 0 | P27: =IF(OR(AG27="n/a",M27="change input"),"n/a",IF(L27="yes",AH27*Z27*AA27*AC27*VLOOKUP(AE27,TRAlookup!$A$2:$H$729,6,FALSE),AH27*Z27*AA27*AC27)) -> 100 | Q27: =IF(OR(M27="n/a",M27="change input"),"n/a",M27/$G$6) -> #DIV/0! | R27: =IF(N27="n/a","n/a",N27/$G$7) -> #DIV/0! | S27: =IF(O27="n/a","n/a",O27/$G$8) -> #DIV/0! | T27: =IF(P27="n/a","n/a",P27/$G$9) -> #DIV/0! | U27: =IF(AND(D27="solid",E27="very low"),"Incorrect fugacity for solids.",IF(AF27="n/a",VLOOKUP(AE27,TRAlookup!$A$2:$H$729,8,FALSE),IF(AND(F27="outdoors",I27="yes"),"Combination 'outdoors' and 'LEV' not allowed. ",IF(AND(C27="prof",F27="indoors - enhanced ventilation",I27="yes"),"Combination 'indoors - enhanced ventilation' and 'LEV' not allowed for professional setting. ",CONCATENATE(AJ27,AK27,AL27))))) | W27: =E27 -> very low | X27: =IF(F27="outdoors",0.7, IF(F27="indoors - good ventilation",0.7, IF(F27="indoors - enhanced ventilation",0.3,1))) -> 1 | Y27: =IF(G27="<15min",0.1, IF(G27="15min-1hr",0.2, IF(G27="1-4hr",0.6,1))) -> 1 | Z27: =IF(AND(D27="solid",OR(W27="medium",W27="high")),1,IF(AND(D27="liquid",OR(W27="very low",W27="low")),1,Y27)) -> 1 | AA27: =IF(H27="<1%",0.1, IF(H27="1-5%",0.2, IF(H27="5-25%",0.6,1))) -> 1 | AB27: =IF(J27="RPE90%",0.1, IF(J27="RPE95%",0.05,1)) -> 1 | AC27: =IF(K27="PPE80%",0.2, IF(K27="PPE90%",0.1, IF(AND(C27="prof",K27="PPE95%"),0.1, IF(K27="PPE95%",0.05,1)))) -> 1 | AD27: =IF(AND(AND(D27="liquid",W27="very low"),NOT(OR(B27="PROC7",B27="PROC11",B27="PROC17",B27="PROC18",AND(B27="PROC10",I27="no"),AND(B27="PROC19",I27="no")))),1,4) -> 1 | AE27: =CONCATENATE(B27,D27,I27,W27,C27) -> PROC15liquidnovery lowind | AF27: =IF(AND(D27="solid",E27="very low"),"n/a",IF(D27="solid",VLOOKUP(AE27,TRAlookup!$A$2:$H$729,2,FALSE),IFERROR(VLOOKUP(AE27,TRAlookup!$A$2:$H$729,2,FALSE)*$B$9/24,"n/a"))) -> 0 | AG27: =IF(AND(D27="solid",E27="very low"),"n/a",VLOOKUP(AE27,TRAlookup!$A$2:$H$729,3,FALSE)) -> 0.34 | AH27: =IF(AND(D27="solid",E27="very low"),"n/a",VLOOKUP(AE27,TRAlookup!$A$2:$H$729,4,FALSE)) -> 100 | AJ27: =IF(AND(D27="liquid",OR(AND(B27="PROC7",C27="ind"),AND(B27="PROC10",I27="no"),AND(B27="PROC11",C27="prof"),OR(B27="PROC17",B27="PROC18"),AND(B27="PROC19",I27="no"))),"Note that the TRA predicts vapour phase exposure; exposure by aerosols is not taken into account; if aerosol formation is relevant, refer to other information or models. ","") | AK27: =IF(AND(B27="PROC1",I27="yes"),"No reduction for LEV for PROC1. ","") | AL27: =IF(Z27>Y27,"No reduction for duration on dermal estimate. ","")
B28: PROC16 | C28: ind | D28: liquid | E28: very low | F28: indoors - no or basic ventilation | G28: >4hr | H28: >25% | I28: no | J28: no RPE | K28: no PPE | L28: no | M28: =IF(AF28="n/a","change input",IF(AND(F28="outdoors",I28="yes"),"change input",IF(AND(C28="prof",F28="indoors - enhanced ventilation",I28="yes"),"change input",AF28*X28*Y28*AA28*AB28*VLOOKUP(AE28,TRAlookup!$A$2:$H$729,5,FALSE)))) -> 0 | N28: =IF(OR(AG28="n/a",M28="change input"),"n/a",IF(L28="yes",AG28*Z28*AA28*AC28*VLOOKUP(AE28,TRAlookup!$A$2:$H$729,6,FALSE),AG28*Z28*AA28*AC28)) -> 0.34 | O28: =IF(OR(M28="n/a",M28="change input"),"n/a",M28*AD28/Y28) -> 0 | P28: =IF(OR(AG28="n/a",M28="change input"),"n/a",IF(L28="yes",AH28*Z28*AA28*AC28*VLOOKUP(AE28,TRAlookup!$A$2:$H$729,6,FALSE),AH28*Z28*AA28*AC28)) -> 100 | Q28: =IF(OR(M28="n/a",M28="change input"),"n/a",M28/$G$6) -> #DIV/0! | R28: =IF(N28="n/a","n/a",N28/$G$7) -> #DIV/0! | S28: =IF(O28="n/a","n/a",O28/$G$8) -> #DIV/0! | T28: =IF(P28="n/a","n/a",P28/$G$9) -> #DIV/0! | U28: =IF(AND(D28="solid",E28="very low"),"Incorrect fugacity for solids.",IF(AF28="n/a",VLOOKUP(AE28,TRAlookup!$A$2:$H$729,8,FALSE),IF(AND(F28="outdoors",I28="yes"),"Combination 'outdoors' and 'LEV' not allowed. ",IF(AND(C28="prof",F28="indoors - enhanced ventilation",I28="yes"),"Combination 'indoors - enhanced ventilation' and 'LEV' not allowed for professional setting. ",CONCATENATE(AJ28,AK28,AL28))))) | W28: =E28 -> very low | X28: =IF(F28="outdoors",0.7, IF(F28="indoors - good ventilation",0.7, IF(F28="indoors - enhanced ventilation",0.3,1))) -> 1 | Y28: =IF(G28="<15min",0.1, IF(G28="15min-1hr",0.2, IF(G28="1-4hr",0.6,1))) -> 1 | Z28: =IF(AND(D28="solid",OR(W28="medium",W28="high")),1,IF(AND(D28="liquid",OR(W28="very low",W28="low")),1,Y28)) -> 1 | AA28: =IF(H28="<1%",0.1, IF(H28="1-5%",0.2, IF(H28="5-25%",0.6,1))) -> 1 | AB28: =IF(J28="RPE90%",0.1, IF(J28="RPE95%",0.05,1)) -> 1 | AC28: =IF(K28="PPE80%",0.2, IF(K28="PPE90%",0.1, IF(AND(C28="prof",K28="PPE95%"),0.1, IF(K28="PPE95%",0.05,1)))) -> 1 | AD28: =IF(AND(AND(D28="liquid",W28="very low"),NOT(OR(B28="PROC7",B28="PROC11",B28="PROC17",B28="PROC18",AND(B28="PROC10",I28="no"),AND(B28="PROC19",I28="no")))),1,4) -> 1 | AE28: =CONCATENATE(B28,D28,I28,W28,C28) -> PROC16liquidnovery lowind | AF28: =IF(AND(D28="solid",E28="very low"),"n/a",IF(D28="solid",VLOOKUP(AE28,TRAlookup!$A$2:$H$729,2,FALSE),IFERROR(VLOOKUP(AE28,TRAlookup!$A$2:$H$729,2,FALSE)*$B$9/24,"n/a"))) -> 0 | AG28: =IF(AND(D28="solid",E28="very low"),"n/a",VLOOKUP(AE28,TRAlookup!$A$2:$H$729,3,FALSE)) -> 0.34 | AH28: =IF(AND(D28="solid",E28="very low"),"n/a",VLOOKUP(AE28,TRAlookup!$A$2:$H$729,4,FALSE)) -> 100 | AJ28: =IF(AND(D28="liquid",OR(AND(B28="PROC7",C28="ind"),AND(B28="PROC10",I28="no"),AND(B28="PROC11",C28="prof"),OR(B28="PROC17",B28="PROC18"),AND(B28="PROC19",I28="no"))),"Note that the TRA predicts vapour phase exposure; exposure by aerosols is not taken into account; if aerosol formation is relevant, refer to other information or models. ","") | AK28: =IF(AND(B28="PROC1",I28="yes"),"No reduction for LEV for PROC1. ","") | AL28: =IF(Z28>Y28,"No reduction for duration on dermal estimate. ","")
